presentable_exception/__init__.py,sha256=7jYJ_bBlQdMgPyw9PlaXKchsv6_W2cxnd6Xx5byiQZw,162
presentable_exception/presentable_exception.py,sha256=YjoRLgER352Z0COK6rGW-A5wKfKRaIFHAgf_aoM9vZc,7483
presentable_exception/with_presentable_exception.py,sha256=f_X-S4Ukm2Akx8cyjHMiBjJM5da73JxLSVJfgHPUNAc,749
django_presentable_exception-0.0.1.dist-info/LICENSE,sha256=xx0jnfkXJvxRnG63LTGOxlggYnIysveWIZ6H3PNdCrQ,11357
django_presentable_exception-0.0.1.dist-info/METADATA,sha256=LjfRlg7lFNKkpHKzbpXh8jPp4-dVdkR-bAr3xBYk79U,2643
django_presentable_exception-0.0.1.dist-info/WHEEL,sha256=ewwEueio1C2XeHTvT17n8dZUJgOvyCWCt0WVNLClP9o,92
django_presentable_exception-0.0.1.dist-info/top_level.txt,sha256=3sILnr_cN-IkWSb_XooGkqU8BpBQwe2x4wq7RsCH8wg,22
django_presentable_exception-0.0.1.dist-info/RECORD,,
